<?xml version='1.0'?>
<sdf version='1.7'>
  <model name='robot'>

    <link name='link'>
      <inertial>
        <mass>0.963128</mass>
        <inertia>
          <ixx>0.254623</ixx>
          <ixy>0</ixy>
          <ixz>0</ixz>
          <iyy>0.103612</iyy>
          <iyz>0</iyz>
          <izz>0.302045</izz>
        </inertia>
        <pose>0 0 0 0 -0 0</pose>
      </inertial>
      <self_collide>0</self_collide>
      <enable_wind>0</enable_wind>
      <kinematic>0</kinematic>
      <pose>0 0 0.373965 0 -0 0</pose>
      <visual name='chassis_visual'>
        <geometry>
          <box>
            <size>0.97 1.68 0.591646</size>
          </box>
        </geometry>
        <material>
          <ambient>0.102 0.294 0.859 1</ambient>
          <diffuse>0.102 0.294 0.859 1</diffuse>
          <specular>0.5 0.5 0.5 1</specular>
        </material>
      </visual>
      
      <collision name='chassis_collision'>
        <laser_retro>0</laser_retro>
        <max_contacts>10</max_contacts>
        <pose>0 0 0 0 -0 0</pose>
        <geometry>
          <box>
            <size>0.97 1.68 0.28</size>
          </box>
        </geometry>
        <surface>
          <friction>
            <ode>
              <mu>1</mu>
              <mu2>1</mu2>
              <fdir1>0 0 0</fdir1>
              <slip1>0</slip1>
              <slip2>0</slip2>
            </ode>
            <torsional>
              <coefficient>1</coefficient>
              <patch_radius>0</patch_radius>
              <surface_radius>0</surface_radius>
              <use_patch_radius>1</use_patch_radius>
              <ode>
                <slip>0</slip>
              </ode>
            </torsional>
          </friction>
          <bounce>
            <restitution_coefficient>0</restitution_coefficient>
            <threshold>1e+06</threshold>
          </bounce>
          <contact>
            <collide_without_contact>0</collide_without_contact>
            <collide_without_contact_bitmask>1</collide_without_contact_bitmask>
            <collide_bitmask>1</collide_bitmask>
            <ode>
              <soft_cfm>0</soft_cfm>
              <soft_erp>0.2</soft_erp>
              <kp>1e+13</kp>
              <kd>1</kd>
              <max_vel>0.01</max_vel>
              <min_depth>0</min_depth>
            </ode>
            <bullet>
              <split_impulse>1</split_impulse>
              <split_impulse_penetration_threshold>-0.01</split_impulse_penetration_threshold>
              <soft_cfm>0</soft_cfm>
              <soft_erp>0.2</soft_erp>
              <kp>1e+13</kp>
              <kd>1</kd>
            </bullet>
          </contact>
        </surface>
      </collision>
      
      <sensor name="lidar_back" type="gpu_lidar">
        <pose>0 0.85 0.2 0 0 1.5708</pose>
        <topic>lidar_back</topic>
        <update_rate>10</update_rate>
        <always_on>1</always_on>
        <visualize>1</visualize>
        <lidar>
            <scan>
            <horizontal>
              <samples>640</samples>
              <resolution>1</resolution>
              <min_angle>-1.6</min_angle>
              <max_angle>1.6</max_angle>
            </horizontal>
            <vertical>
              <samples>1</samples>
              <resolution>1</resolution>
              <min_angle>-0.1</min_angle>
              <max_angle>0.1</max_angle>
            </vertical>
          </scan>
          <range>
            <min>0.08</min>
            <max>10.0</max>
            <resolution>0.01</resolution>
          </range>
        </lidar>
        <alwaysOn>1</alwaysOn>
        <visualize>true</visualize>
      </sensor>

  
      <sensor name="lidar_front" type="gpu_lidar">
        <pose>0 -0.8 0.2 0 0 -1.5708</pose>
        <topic>lidar_front</topic>
        <update_rate>10</update_rate>
        <always_on>1</always_on>
        <visualize>1</visualize>
        <lidar>
            <scan>
            <horizontal>
              <samples>640</samples>
              <resolution>1</resolution>
              <min_angle>-1.6</min_angle>
              <max_angle>1.6</max_angle>
            </horizontal>
            <vertical>
              <samples>1</samples>
              <resolution>1</resolution>
              <min_angle>-0.1</min_angle>
              <max_angle>0.1</max_angle>
            </vertical>
          </scan>
          <range>
            <min>0.1</min>
            <max>25</max>
            <resolution>0.01</resolution>
          </range>
        </lidar>
        <alwaysOn>1</alwaysOn>
        <visualize>true</visualize>
      </sensor>

    </link>

    <link name='link_0'>
      <inertial>
        <mass>0.00987023</mass>
        <inertia>
          <ixx>0.00082989</ixx>
          <ixy>0</ixy>
          <ixz>0</ixz>
          <iyy>0.00083146</iyy>
          <iyz>0</iyz>
          <izz>1.632e-05</izz>
        </inertia>
        <pose>0 0 0 0 -0 0</pose>
      </inertial>
      <pose>-0.0075 -0.715 1.16917 0 -0 0</pose>
      <gravity>1</gravity>
      <self_collide>0</self_collide>
      <kinematic>0</kinematic>
      <enable_wind>0</enable_wind>
      <visual name='visual'>
        <pose>0 0 0 0 -0 0</pose>
        <geometry>
          <box>
            <size>0.1 0.1 1</size>
          </box>
        </geometry>
        <material>
          <lighting>1</lighting>
          <script>
            <uri>file://media/materials/scripts/gazebo.material</uri>
            <name>Gazebo/Grey</name>
          </script>
          <shader type='pixel'>
            <normal_map>__default__</normal_map>
          </shader>
          <ambient>0.3 0.3 0.3 1</ambient>
          <diffuse>0.7 0.7 0.7 1</diffuse>
          <specular>0.01 0.01 0.01 1</specular>
          <emissive>0 0 0 1</emissive>
        </material>
        <transparency>0</transparency>
        <cast_shadows>1</cast_shadows>
      </visual>
      <collision name='collision'>
        <laser_retro>0</laser_retro>
        <max_contacts>10</max_contacts>
        <pose>0 0 0 0 -0 0</pose>
        <geometry>
          <box>
            <size>0.104281 0.094668 1</size>
          </box>
        </geometry>
        <surface>
          <friction>
            <ode>
              <mu>1</mu>
              <mu2>1</mu2>
              <fdir1>0 0 0</fdir1>
              <slip1>0</slip1>
              <slip2>0</slip2>
            </ode>
            <torsional>
              <coefficient>1</coefficient>
              <patch_radius>0</patch_radius>
              <surface_radius>0</surface_radius>
              <use_patch_radius>1</use_patch_radius>
              <ode>
                <slip>0</slip>
              </ode>
            </torsional>
          </friction>
          <bounce>
            <restitution_coefficient>0</restitution_coefficient>
            <threshold>1e+06</threshold>
          </bounce>
          <contact>
            <collide_without_contact>0</collide_without_contact>
            <collide_without_contact_bitmask>1</collide_without_contact_bitmask>
            <collide_bitmask>1</collide_bitmask>
            <ode>
              <soft_cfm>0</soft_cfm>
              <soft_erp>0.2</soft_erp>
              <kp>1e+13</kp>
              <kd>1</kd>
              <max_vel>0.01</max_vel>
              <min_depth>0</min_depth>
            </ode>
            <bullet>
              <split_impulse>1</split_impulse>
              <split_impulse_penetration_threshold>-0.01</split_impulse_penetration_threshold>
              <soft_cfm>0</soft_cfm>
              <soft_erp>0.2</soft_erp>
              <kp>1e+13</kp>
              <kd>1</kd>
            </bullet>
          </contact>
        </surface>
      </collision>
    </link>

    <link name='wheel_fl'>
      <pose>0.53 -0.86 0 3.14 1.57 3.14</pose>
      <visual name='wheel_fl_visual'>
        <geometry>
          <cylinder>
            <radius>0.5</radius>
            <length>0.1</length>
          </cylinder>
        </geometry>
         <material>
          <ambient>0.0118 0.0118 0.0118 1</ambient>
          <diffuse>0.0118 0.0118 0.0118 1</diffuse>
          <specular>0.5 0.5 0.5 1</specular>
        </material>
      </visual>
      <collision name='wheel_fl_collision'>
        <geometry>
          <cylinder>
            <radius>0.5</radius>
            <length>0.1</length>
          </cylinder>
        </geometry>
      </collision>
    </link>
    <link name='wheel_fr'>
      <pose>-0.53 -0.89 0 3.14 1.57 3.14</pose>
      <visual name='wheel_fr_visual'>
        <geometry>
          <cylinder>
            <radius>0.5</radius>
            <length>0.1</length>
          </cylinder>
        </geometry>
         <material>
          <ambient>0.0118 0.0118 0.0118 1</ambient>
          <diffuse>0.0118 0.0118 0.0118 1</diffuse>
          <specular>0.5 0.5 0.5 1</specular>
        </material>
      </visual>
      <collision name='wheel_fr_collision'>
        <geometry>
          <cylinder>
            <radius>0.5</radius>
            <length>0.1</length>
          </cylinder>
        </geometry>
      </collision>
    </link>

    <link name='wheel_bl'>
      <pose>0.53 0.34 0 3.14 1.57 3.14</pose>
      <visual name='wheel_bl_visual'>
        <geometry>
          <cylinder>
            <radius>0.5</radius>
            <length>0.1</length>
          </cylinder>
        </geometry>
         <material>
          <ambient>0.0118 0.0118 0.0118 1</ambient>
          <diffuse>0.0118 0.0118 0.0118 1</diffuse>
          <specular>0.5 0.5 0.5 1</specular>
        </material>
      </visual>
      <collision name='wheel_bl_collision'>
        <geometry>
          <cylinder>
            <radius>0.5</radius>
            <length>0.1</length>
          </cylinder>
        </geometry>
      </collision>
    </link>

    <link name='wheel_br'>
      <pose>-0.53 0.34 0 3.14 1.57 3.14</pose>
      <visual name='wheel_br_visual'>
        <geometry>
          <cylinder>
            <radius>0.5</radius>
            <length>0.1</length>
          </cylinder>
        </geometry>
         <material>
          <ambient>0.0118 0.0118 0.0118 1</ambient>
          <diffuse>0.0118 0.0118 0.0118 1</diffuse>
          <specular>0.5 0.5 0.5 1</specular>
        </material>
      </visual>
      <collision name='wheel_br_collision'>
        <geometry>
          <cylinder>
            <radius>0.5</radius>
            <length>0.1</length>
          </cylinder>
        </geometry>
      </collision>
    </link>

    <model name='camera'>
      <pose>-0.007084 -0.713487 1.71975 3.14159 0 -1.5708</pose>
      <static>0</static>
      <link name='link'>
        <inertial>
          <mass>0.1</mass>
          <inertia>
            <ixx>0.000166667</ixx>
            <iyy>0.000166667</iyy>
            <izz>0.000166667</izz>
            <ixy>0</ixy>
            <ixz>0</ixz>
            <iyz>0</iyz>
          </inertia>
          <pose>0 0 0 0 0 0</pose>
        </inertial>
        <collision name='collision'>
          <geometry>
            <box>
              <size>0.1 0.1 0.1</size>
            </box>
          </geometry>
          <max_contacts>10</max_contacts>
          <surface>
            <contact>
              <ode/>
            </contact>
            <bounce/>
            <friction>
              <torsional>
                <ode/>
              </torsional>
              <ode/>
            </friction>
          </surface>
        </collision>
        <visual name='visual'>
          <geometry>
            <box>
              <size>0.1 0.1 0.1</size>
            </box>
          </geometry>
        </visual>
        <sensor name='camera' type='camera'>
          <camera>
            <horizontal_fov>1.67</horizontal_fov>
            <image>
              <width>320</width>
              <height>240</height>
            </image>
            <clip>
              <near>0.1</near>
              <far>100</far>
            </clip>
          </camera>
          <always_on>1</always_on>
          <update_rate>30</update_rate>
          <visualize>1</visualize>
        </sensor>
        <self_collide>0</self_collide>
        <enable_wind>0</enable_wind>
        <kinematic>0</kinematic>
      </link>
    </model>

    <joint name='joint_fl' type='revolute'>
      <parent>link</parent>
      <child>wheel_fl</child>
    </joint>

    <joint name='joint_fr' type='revolute'>
      <parent>link</parent>
      <child>wheel_fr</child>
    </joint>

    <joint name='joint_bl' type='revolute'>
      <parent>link</parent>
      <child>wheel_bl</child>
    </joint>

    <joint name='joint_br' type='revolute'>
      <parent>link</parent>
      <child>wheel_br</child>
    </joint>

    <joint name='link_0_JOINT_1' type='revolute'>
      <parent>link_0</parent>
      <child>camera::link</child>
      <pose>0 0 0 0 0 0</pose>
      <physics>
        <ode>
          <limit>
            <cfm>0</cfm>
            <erp>0.2</erp>
          </limit>
          <suspension>
            <cfm>0</cfm>
            <erp>0.2</erp>
          </suspension>
        </ode>
      </physics>
    </joint>

    <joint name='link_JOINT_0' type='fixed'>
      <parent>link</parent>
      <child>link_0</child>
      <pose>0 0 0 0 0 0</pose>
      <physics>
        <ode>
          <limit>
            <cfm>0</cfm>
            <erp>0.2</erp>
          </limit>
          <suspension>
            <cfm>0</cfm>
            <erp>0.2</erp>
          </suspension>
        </ode>
      </physics>
    </joint>
    
    <plugin
      filename="libignition-gazebo-diff-drive-system.so"
      name="ignition::gazebo::systems::DiffDrive">

      <left_joint>joint_fl</left_joint>
      <right_joint>joint_fr</right_joint>

      <wheel_separation>0.7</wheel_separation>
      <wheel_radius>0.5</wheel_radius>

      <topic>cmd_vel</topic>

      <odom_publish_frequency>10</odom_publish_frequency>
    </plugin>
    <plugin
      filename="libignition-gazebo-sensors-system.so"
      name="ignition::gazebo::systems::Sensors">
    </plugin>
    <static>0</static>
    <allow_auto_disable>0</allow_auto_disable>
  </model>
</sdf>
